Workbook

Sheet Purchase Order
D1: WORLD COMMUNICATION GIRLS SCHOOL ROAD, NEAR RAM MANDIR, KATIHAR, BIHAR - 854105 Abhishek.kumar@worldcommunication.in | Ph: 9284891845 | GSTIN: 10ALQPK7914E1Z8 | M1: AW_Crore | N1: AW_Lakh | O1: AW_Thousand | P1: AW_Hundred | Q1: AW_Last2 | R1: AW_Paise | T1: AW_CroreWord | U1: AW_LakhWord | V1: AW_ThousandWord | W1: AW_HundredWord | X1: AW_Last2Word | Y1: AW_PaiseWord
M2: =INT(K38/10000000) -> 0 | N2: =MOD(INT(K38/100000),100) -> 0 | O2: =MOD(INT(K38/1000),100) -> 0 | P2: =MOD(INT(K38/100),10) -> 0 | Q2: =MOD(K38,100) -> 0 | R2: =ROUND((K38-INT(K38))*100,0) -> 0 | T2: =IF(M2=0,"",VLOOKUP(M2,AmountWords!$A$1:$B$100,2,FALSE())&" Crore") | U2: =IF(N2=0,"",VLOOKUP(N2,AmountWords!$A$1:$B$100,2,FALSE())&" Lakh") | V2: =IF(O2=0,"",VLOOKUP(O2,AmountWords!$A$1:$B$100,2,FALSE())&" Thousand") | W2: =IF(P2=0,"",VLOOKUP(P2,AmountWords!$A$1:$B$100,2,FALSE())&" Hundred") | X2: =IF(Q2=0,"",VLOOKUP(Q2,AmountWords!$A$1:$B$100,2,FALSE())) | Y2: =IF(R2=0,"","and "&VLOOKUP(R2,AmountWords!$A$1:$B$100,2,FALSE())&" Paise")
C3: PURCHASE ORDER
A5: PO No. | C5: WC/PO/________________ | F5: SUPPLIER / VENDOR DETAILS Company Name: __________________________ Address: _______________________________ GSTIN: ______________ State: ____________ Contact Person: _________________________ Email: __________________________________ Phone: __________________________________
A6: PO Date | C6: __/__/____
A7: Delivery Due Date | C7: __/__/____
A8: Payment Terms | C8: 30% Advance with PO, Rest 70% before Dispatch
A9: Delivery Terms | C9: Ex-Works / To Pay
A10: Currency | C10: INR
A13: BILL TO: WORLD COMMUNICATION Girls School Road, Near Ram Mandir, Katihar, Bihar - 854105 GSTIN: 10ALQPK7914E1Z8 | F13: SHIP TO: WORLD COMMUNICATION Girls School Road, Near Ram Mandir, Katihar, Bihar - 854105 GSTIN: 10ALQPK7914E1Z8
A18: S. No. | B18: Description of Goods / Services | E18: Model / Part No. | G18: HSN/SAC | H18: Qty | I18: Rate (₹) | J18: Amount (₹)
A19: 1 | J19: =IF(OR(H19="",I19=""),"",H19*I19)
A20: 2 | J20: =IF(OR(H20="",I20=""),"",H20*I20)
A21: 3 | J21: =IF(OR(H21="",I21=""),"",H21*I21)
A22: 4 | J22: =IF(OR(H22="",I22=""),"",H22*I22)
A23: 5 | J23: =IF(OR(H23="",I23=""),"",H23*I23)
A24: 6 | J24: =IF(OR(H24="",I24=""),"",H24*I24)
A25: 7 | J25: =IF(OR(H25="",I25=""),"",H25*I25)
A26: 8 | J26: =IF(OR(H26="",I26=""),"",H26*I26)
A27: 9 | J27: =IF(OR(H27="",I27=""),"",H27*I27)
A28: 10 | J28: =IF(OR(H28="",I28=""),"",H28*I28)
A29: SPECIAL INSTRUCTIONS / NOTES | G29: Sub Total (₹) | K29: =SUM(J19:J28) -> 0
G30: Courier / Other Charges (₹)
G31: Taxable Amount (₹) | K31: =K29+K30 -> 0
G32: GST MODE (Select) | J32: CGST + SGST | K32: Amount (₹)
G33: CGST @ 9% (₹) | J33: 9.00% | K33: =IF(J32="CGST + SGST",K31*9%,K31*9%) -> 0
G34: SGST @ 9% (₹) | J34: 9.00% | K34: =IF(J32="CGST + SGST",K31*9%,0) -> 0
G35: IGST @ 9% (₹) | J35: 9.00% | K35: =IF(J32="CGST + IGST",K31*9%,0) -> 0
G36: TOTAL GST (₹) | K36: =SUM(K33:K35) -> 0
G37: Round Off (₹)
A38: =IF(K38="","","Amount in Words: "&IF(K38=0,"Rupees Zero Only","Rupees "&TRIM(T2&" "&U2&" "&V2&" "&W2&" "&X2&" "&Y2)&" Only")) -> Amount in Words: Rupees Zero Only | G38: GRAND TOTAL (₹) | K38: =K31+K36+K37 -> 0
A40: BANK DETAILS Account Holder: WORLD COMMUNICATION Bank Name: State Bank of India Account Number: 32204185051 Branch: (12637) DURGASTHAN KATIHAR IFSC Code: SBIN0012637 | G40: FOR WORLD COMMUNICATION _______________________________ Authorised Signatory
A45: TERMS AND CONDITIONS:
A46: 1 | B46: Scope | C46: Supplier shall supply goods/services strictly as per PO specifications, quantity, and delivery schedule.
A47: 2 | B47: Price | C47: Prices are firm and inclusive/exclusive of taxes as mentioned in the PO. No variation is allowed without written approval of the Purchaser.
A48: 3 | B48: Delivery | C48: 30% Payment along with the PO and PDC Delivery shall be applicable within the stipulated time i.e. 20 Days From the date of Shipment.
A49: 4 | B49: Termination | C49: Purchaser reserves the right to terminate the PO partially or fully in case of breach, delay.
A50: 5 | B50: Force Majeure | C50: Neither party shall be liable for delays due to force majeure conditions.
A51: 6 | B51: Warranty | C51: Supplier shall provide warranty as per OEM/manufacturer terms from the date of acceptance.
A53: This is a Computer Generated Document E. & O.E.

Sheet Performa Invoice
D1: WORLD COMMUNICATION GIRLS SCHOOL ROAD, NEAR RAM MANDIR, KATIHAR, BIHAR - 854105 Abhishek.kumar@worldcommunication.in | Ph: 9284891845 | GSTIN: 10ALQPK7914E1Z8 | M1: AW_Crore | N1: AW_Lakh | O1: AW_Thousand | P1: AW_Hundred | Q1: AW_Last2 | R1: AW_Paise | T1: AW_CroreWord | U1: AW_LakhWord | V1: AW_ThousandWord | W1: AW_HundredWord | X1: AW_Last2Word | Y1: AW_PaiseWord
M2: =INT(K38/10000000) -> 0 | N2: =MOD(INT(K38/100000),100) -> 0 | O2: =MOD(INT(K38/1000),100) -> 0 | P2: =MOD(INT(K38/100),10) -> 0 | Q2: =MOD(K38,100) -> 0 | R2: =ROUND((K38-INT(K38))*100,0) -> 0 | T2: =IF(M2=0,"",VLOOKUP(M2,AmountWords!$A$1:$B$100,2,FALSE())&" Crore") | U2: =IF(N2=0,"",VLOOKUP(N2,AmountWords!$A$1:$B$100,2,FALSE())&" Lakh") | V2: =IF(O2=0,"",VLOOKUP(O2,AmountWords!$A$1:$B$100,2,FALSE())&" Thousand") | W2: =IF(P2=0,"",VLOOKUP(P2,AmountWords!$A$1:$B$100,2,FALSE())&" Hundred") | X2: =IF(Q2=0,"",VLOOKUP(Q2,AmountWords!$A$1:$B$100,2,FALSE())) | Y2: =IF(R2=0,"","and "&VLOOKUP(R2,AmountWords!$A$1:$B$100,2,FALSE())&" Paise")
C3: PERFORMA INVOICE
A5: PI No. | C5: WC/PI/________________ | F5: BUYER DETAILS Company Name: __________________________ Address: _______________________________ GSTIN: ______________ State: ____________ Contact Person: _________________________ Email: __________________________________ Phone: __________________________________
A6: PI Date | C6: __/__/____
A7: Valid Till | C7: __/__/____
A8: Payment Terms | C8: 30% Advance with PO, Rest 70% before Dispatch
A9: Delivery Terms | C9: Ex-Works / To Pay
A10: Currency | C10: INR
A13: BILL TO: WORLD COMMUNICATION Girls School Road, Near Ram Mandir, Katihar, Bihar - 854105 GSTIN: 10ALQPK7914E1Z8 | F13: SHIP TO: WORLD COMMUNICATION Girls School Road, Near Ram Mandir, Katihar, Bihar - 854105 GSTIN: 10ALQPK7914E1Z8
A18: S. No. | B18: Description of Goods / Services | E18: Model / Part No. | G18: HSN/SAC | H18: Qty | I18: Rate (₹) | J18: Amount (₹)
A19: 1 | J19: =IF(OR(H19="",I19=""),"",H19*I19)
A20: 2 | J20: =IF(OR(H20="",I20=""),"",H20*I20)
A21: 3 | J21: =IF(OR(H21="",I21=""),"",H21*I21)
A22: 4 | J22: =IF(OR(H22="",I22=""),"",H22*I22)
A23: 5 | J23: =IF(OR(H23="",I23=""),"",H23*I23)
A24: 6 | J24: =IF(OR(H24="",I24=""),"",H24*I24)
A25: 7 | J25: =IF(OR(H25="",I25=""),"",H25*I25)
A26: 8 | J26: =IF(OR(H26="",I26=""),"",H26*I26)
A27: 9 | J27: =IF(OR(H27="",I27=""),"",H27*I27)
A28: 10 | J28: =IF(OR(H28="",I28=""),"",H28*I28)
A29: SPECIAL INSTRUCTIONS / NOTES | G29: Sub Total (₹) | K29: =SUM(J19:J28) -> 0
G30: Courier / Other Charges (₹)
G31: Taxable Amount (₹) | K31: =K29+K30 -> 0
G32: GST MODE (Select) | J32: CGST + SGST | K32: Amount (₹)
G33: CGST @ 9% (₹) | J33: 9.00% | K33: =IF(J32="CGST + SGST",K31*9%,K31*9%) -> 0
G34: SGST @ 9% (₹) | J34: 9.00% | K34: =IF(J32="CGST + SGST",K31*9%,0) -> 0
G35: IGST @ 9% (₹) | J35: 9.00% | K35: =IF(J32="CGST + IGST",K31*9%,0) -> 0
G36: TOTAL GST (₹) | K36: =SUM(K33:K35) -> 0
G37: Round Off (₹)
A38: =IF(K38="","","Amount in Words: "&IF(K38=0,"Rupees Zero Only","Rupees "&TRIM(T2&" "&U2&" "&V2&" "&W2&" "&X2&" "&Y2)&" Only")) -> Amount in Words: Rupees Zero Only | G38: GRAND TOTAL (₹) | K38: =K31+K36+K37 -> 0
A40: BANK DETAILS Account Holder: WORLD COMMUNICATION Bank Name: State Bank of India Account Number: 32204185051 Branch: (12637) DURGASTHAN KATIHAR IFSC Code: SBIN0012637 | G40: FOR WORLD COMMUNICATION _______________________________ Authorised Signatory
A45: TERMS AND CONDITIONS:
A46: 1 | B46: Scope | C46: Supplier shall supply goods/services strictly as per PO specifications, quantity, and delivery schedule.
A47: 2 | B47: Price | C47: Prices are firm and inclusive/exclusive of taxes as mentioned in the PO. No variation is allowed without written approval of the Purchaser.
A48: 3 | B48: Delivery | C48: 30% Payment along with the PO and PDC Delivery shall be applicable within the stipulated time i.e. 20 Days From the date of Shipment.
A49: 4 | B49: Termination | C49: Purchaser reserves the right to terminate the PO partially or fully in case of breach, delay.
A50: 5 | B50: Force Majeure | C50: Neither party shall be liable for delays due to force majeure conditions.
A51: 6 | B51: Warranty | C51: Supplier shall provide warranty as per OEM/manufacturer terms from the date of acceptance.
A53: This is a Computer Generated Document E. & O.E.

Sheet Tax Invoice
D1: WORLD COMMUNICATION GIRLS SCHOOL ROAD, NEAR RAM MANDIR, KATIHAR, BIHAR - 854105 Abhishek.kumar@worldcommunication.in | Ph: 9284891845 | GSTIN: 10ALQPK7914E1Z8 | M1: AW_Crore | N1: AW_Lakh | O1: AW_Thousand | P1: AW_Hundred | Q1: AW_Last2 | R1: AW_Paise | T1: AW_CroreWord | U1: AW_LakhWord | V1: AW_ThousandWord | W1: AW_HundredWord | X1: AW_Last2Word | Y1: AW_PaiseWord
M2: =INT(K38/10000000) -> 0 | N2: =MOD(INT(K38/100000),100) -> 0 | O2: =MOD(INT(K38/1000),100) -> 0 | P2: =MOD(INT(K38/100),10) -> 0 | Q2: =MOD(K38,100) -> 0 | R2: =ROUND((K38-INT(K38))*100,0) -> 0 | T2: =IF(M2=0,"",VLOOKUP(M2,AmountWords!$A$1:$B$100,2,FALSE())&" Crore") | U2: =IF(N2=0,"",VLOOKUP(N2,AmountWords!$A$1:$B$100,2,FALSE())&" Lakh") | V2: =IF(O2=0,"",VLOOKUP(O2,AmountWords!$A$1:$B$100,2,FALSE())&" Thousand") | W2: =IF(P2=0,"",VLOOKUP(P2,AmountWords!$A$1:$B$100,2,FALSE())&" Hundred") | X2: =IF(Q2=0,"",VLOOKUP(Q2,AmountWords!$A$1:$B$100,2,FALSE())) | Y2: =IF(R2=0,"","and "&VLOOKUP(R2,AmountWords!$A$1:$B$100,2,FALSE())&" Paise")
C3: TAX INVOICE
A5: Invoice No. | C5: WC/INV/________________ | F5: BUYER DETAILS Company Name: __________________________ Address: _______________________________ GSTIN: ______________ State: ____________ Contact Person: _________________________ Email: __________________________________ Phone: __________________________________
A6: Invoice Date | C6: __/__/____
A7: PO No. | C7: ________________
A8: PO Date | C8: __/__/____
A9: Payment Terms | C9: 30% Advance with PO, Rest 70% before Dispatch
A10: Place of Supply | C10: ________________
A11: Currency | C11: INR
A13: BILL TO: WORLD COMMUNICATION Girls School Road, Near Ram Mandir, Katihar, Bihar - 854105 GSTIN: 10ALQPK7914E1Z8 | F13: SHIP TO: WORLD COMMUNICATION Girls School Road, Near Ram Mandir, Katihar, Bihar - 854105 GSTIN: 10ALQPK7914E1Z8
A18: S. No. | B18: Description of Goods / Services | E18: Model / Part No. | G18: HSN/SAC | H18: Qty | I18: Rate (₹) | J18: Amount (₹)
A19: 1 | J19: =IF(OR(H19="",I19=""),"",H19*I19)
A20: 2 | J20: =IF(OR(H20="",I20=""),"",H20*I20)
A21: 3 | J21: =IF(OR(H21="",I21=""),"",H21*I21)
A22: 4 | J22: =IF(OR(H22="",I22=""),"",H22*I22)
A23: 5 | J23: =IF(OR(H23="",I23=""),"",H23*I23)
A24: 6 | J24: =IF(OR(H24="",I24=""),"",H24*I24)
A25: 7 | J25: =IF(OR(H25="",I25=""),"",H25*I25)
A26: 8 | J26: =IF(OR(H26="",I26=""),"",H26*I26)
A27: 9 | J27: =IF(OR(H27="",I27=""),"",H27*I27)
A28: 10 | J28: =IF(OR(H28="",I28=""),"",H28*I28)
A29: SPECIAL INSTRUCTIONS / NOTES | G29: Sub Total (₹) | K29: =SUM(J19:J28) -> 0
G30: Courier / Other Charges (₹)
G31: Taxable Amount (₹) | K31: =K29+K30 -> 0
G32: GST MODE (Select) | J32: CGST + SGST | K32: Amount (₹)
G33: CGST @ 9% (₹) | J33: 9.00% | K33: =IF(J32="CGST + SGST",K31*9%,K31*9%) -> 0
G34: SGST @ 9% (₹) | J34: 9.00% | K34: =IF(J32="CGST + SGST",K31*9%,0) -> 0
G35: IGST @ 9% (₹) | J35: 9.00% | K35: =IF(J32="CGST + IGST",K31*9%,0) -> 0
G36: TOTAL GST (₹) | K36: =SUM(K33:K35) -> 0
G37: Round Off (₹)
A38: =IF(K38="","","Amount in Words: "&IF(K38=0,"Rupees Zero Only","Rupees "&TRIM(T2&" "&U2&" "&V2&" "&W2&" "&X2&" "&Y2)&" Only")) -> Amount in Words: Rupees Zero Only | G38: GRAND TOTAL (₹) | K38: =K31+K36+K37 -> 0
A40: BANK DETAILS Account Holder: WORLD COMMUNICATION Bank Name: State Bank of India Account Number: 32204185051 Branch: (12637) DURGASTHAN KATIHAR IFSC Code: SBIN0012637 | G40: FOR WORLD COMMUNICATION _______________________________ Authorised Signatory
A45: TERMS AND CONDITIONS:
A46: 1 | B46: Scope | C46: Supplier shall supply goods/services strictly as per PO specifications, quantity, and delivery schedule.
A47: 2 | B47: Price | C47: Prices are firm and inclusive/exclusive of taxes as mentioned in the PO. No variation is allowed without written approval of the Purchaser.
A48: 3 | B48: Delivery | C48: 30% Payment along with the PO and PDC Delivery shall be applicable within the stipulated time i.e. 20 Days From the date of Shipment.
A49: 4 | B49: Termination | C49: Purchaser reserves the right to terminate the PO partially or fully in case of breach, delay.
A50: 5 | B50: Force Majeure | C50: Neither party shall be liable for delays due to force majeure conditions.
A51: 6 | B51: Warranty | C51: Supplier shall provide warranty as per OEM/manufacturer terms from the date of acceptance.
...

Sheet AmountWords
A1: 0 | B1: Zero
A2: 1 | B2: One | X2: =IF(Q2=0,"",VLOOKUP(Q2,AmountWords!$A$1:$B$100,2,FALSE()))
A3: 2 | B3: Two
A4: 3 | B4: Three
A5: 4 | B5: Four
A6: 5 | B6: Five
A7: 6 | B7: Six
A8: 7 | B8: Seven
A9: 8 | B9: Eight
A10: 9 | B10: Nine
A11: 10 | B11: Ten
A12: 11 | B12: Eleven
A13: 12 | B13: Twelve
A14: 13 | B14: Thirteen
... A37: 36 | B37: Thirty Six
A38: =IF(K38="","","Amount in Words: "&IF(K38=0,"Rupees Zero Only","Rupees "&TRIM(T2&" "&U2&" "&V2&" "&W2&" "&X2&" "&Y2)&" Only")) | B38: Thirty Seven
A39: 38 | B39: Thirty Eight
A40: 39 | B40: Thirty Nine
A41: 40 | B41: Forty
A42: 41 | B42: Forty One
A43: 42 | B43: Forty Two
A44: 43 | B44: Forty Three
A45: 44 | B45: Forty Four
A46: 45 | B46: Forty Five
A47: 46 | B47: Forty Six
A48: 47 | B48: Forty Seven
A49: 48 | B49: Forty Eight
A50: 49 | B50: Forty Nine
... A100: 99 | B100: Ninety Nine
